Workbook
Name Iller: 'Müşteriler'!$F$2:$F$11
Name Aylar: 'Müşteriler'!$H$2:$H$13
Name Musteriler: 'Müşteriler'!$A$2:$A$101

Sheet Panel
A1: SATIŞ & TAHSİLAT
A2: İl bazında aylık görünüm / TASLAK · Tamamı kurgusal örnek veridir | N2: =YEAR(DATE(LEFT(B4,4),RIGHT(B4,2)-1,1))&"-"&RIGHT("0"&MONTH(DATE(LEFT(B4,4),RIGHT(B4,2)-1,1)),2) -> 2026-09
N3: =SUM(F12:F21) -> 779926.7
A4: GÖRÜNTÜLENEN AY | B4: 2026-10 | C4: Ayı listeden seçin · Tüm özetler ve grafik güncellenir | H4: VERİ KAPSAMI / EYLÜL + EKİM 2026 | N4: =COUNTIFS('Banka Dökümü'!$E$2:$E$2001,$B$4,'Banka Dökümü'!$H$2:$H$2001,"Eşleşmedi") -> 3
A6: Toplam satış | C6: Gelen ödeme | E6: Kalan alacak | H6: Geçen aya göre satış farkı %
A7: =SUM(B12:B21) -> 776624.32 | C7: =SUM(C12:C21) -> 568161.01 | E7: =A7-C7 -> 208463.31 | H7: =IF($N$3=0,"",A7/$N$3-1) -> -0.0042342184
A8: Seçilen ayın faturaları | C8: Eşleşen pozitif banka girişleri | E8: Seçilen ay: satış − tahsilat | H8: =IF($N$3=0,"Önceki ay satış yok / oran hesaplanmadı","Önceki ay satışına göre değişim") -> Önceki ay satışına göre değişim
A10: İLLERE GÖRE AYLIK ÖZET | H10: İL BAZLI SATIŞ / ₺
A11: İl | B11: Satış | C11: Ödeme | D11: Kalan alacak | E11: Tahsilat oranı | F11: Geçen ay satış
A12: İstanbul | B12: =SUMIFS('Satışlar'!$E$2:$E$2001,'Satışlar'!$F$2:$F$2001,$B$4,'Satışlar'!$D$2:$D$2001,A12) -> 66089.95 | C12: =SUMIFS('Banka Dökümü'!$C$2:$C$2001,'Banka Dökümü'!$E$2:$E$2001,$B$4,'Banka Dökümü'!$G$2:$G$2001,A12,'Banka Dökümü'!$H$2:$H$2001,"Eşleşti") -> 49805.9 | D12: =B12-C12 -> 16284.05 | E12: =IFERROR(C12/B12,0) -> 0.75360777 | F12: =SUMIFS('Satışlar'!$E$2:$E$2001,'Satışlar'!$F$2:$F$2001,$N$2,'Satışlar'!$D$2:$D$2001,A12) -> 83683.73
A13: Ankara | B13: =SUMIFS('Satışlar'!$E$2:$E$2001,'Satışlar'!$F$2:$F$2001,$B$4,'Satışlar'!$D$2:$D$2001,A13) -> 68957.69 | C13: =SUMIFS('Banka Dökümü'!$C$2:$C$2001,'Banka Dökümü'!$E$2:$E$2001,$B$4,'Banka Dökümü'!$G$2:$G$2001,A13,'Banka Dökümü'!$H$2:$H$2001,"Eşleşti") -> 52093.22 | D13: =B13-C13 -> 16864.47 | E13: =IFERROR(C13/B13,0) -> 0.75543743 | F13: =SUMIFS('Satışlar'!$E$2:$E$2001,'Satışlar'!$F$2:$F$2001,$N$2,'Satışlar'!$D$2:$D$2001,A13) -> 110101.21
A14: İzmir | B14: =SUMIFS('Satışlar'!$E$2:$E$2001,'Satışlar'!$F$2:$F$2001,$B$4,'Satışlar'!$D$2:$D$2001,A14) -> 122859.59 | C14: =SUMIFS('Banka Dökümü'!$C$2:$C$2001,'Banka Dökümü'!$E$2:$E$2001,$B$4,'Banka Dökümü'!$G$2:$G$2001,A14,'Banka Dökümü'!$H$2:$H$2001,"Eşleşti") -> 88140.1 | D14: =B14-C14 -> 34719.49 | E14: =IFERROR(C14/B14,0) -> 0.71740513 | F14: =SUMIFS('Satışlar'!$E$2:$E$2001,'Satışlar'!$F$2:$F$2001,$N$2,'Satışlar'!$D$2:$D$2001,A14) -> 93888.59
A15: Bursa | B15: =SUMIFS('Satışlar'!$E$2:$E$2001,'Satışlar'!$F$2:$F$2001,$B$4,'Satışlar'!$D$2:$D$2001,A15) -> 107585.76 | C15: =SUMIFS('Banka Dökümü'!$C$2:$C$2001,'Banka Dökümü'!$E$2:$E$2001,$B$4,'Banka Dökümü'!$G$2:$G$2001,A15,'Banka Dökümü'!$H$2:$H$2001,"Eşleşti") -> 77589.15 | D15: =B15-C15 -> 29996.61 | E15: =IFERROR(C15/B15,0) -> 0.7211842 | F15: =SUMIFS('Satışlar'!$E$2:$E$2001,'Satışlar'!$F$2:$F$2001,$N$2,'Satışlar'!$D$2:$D$2001,A15) -> 96063.97
A16: Antalya | B16: =SUMIFS('Satışlar'!$E$2:$E$2001,'Satışlar'!$F$2:$F$2001,$B$4,'Satışlar'!$D$2:$D$2001,A16) -> 59467.29 | C16: =SUMIFS('Banka Dökümü'!$C$2:$C$2001,'Banka Dökümü'!$E$2:$E$2001,$B$4,'Banka Dökümü'!$G$2:$G$2001,A16,'Banka Dökümü'!$H$2:$H$2001,"Eşleşti") -> 39252.63 | D16: =B16-C16 -> 20214.66 | E16: =IFERROR(C16/B16,0) -> 0.66007094 | F16: =SUMIFS('Satışlar'!$E$2:$E$2001,'Satışlar'!$F$2:$F$2001,$N$2,'Satışlar'!$D$2:$D$2001,A16) -> 93690.91
A17: Konya | B17: =SUMIFS('Satışlar'!$E$2:$E$2001,'Satışlar'!$F$2:$F$2001,$B$4,'Satışlar'!$D$2:$D$2001,A17) -> 88673.36 | C17: =SUMIFS('Banka Dökümü'!$C$2:$C$2001,'Banka Dökümü'!$E$2:$E$2001,$B$4,'Banka Dökümü'!$G$2:$G$2001,A17,'Banka Dökümü'!$H$2:$H$2001,"Eşleşti") -> 62929.81 | D17: =B17-C17 -> 25743.55 | E17: =IFERROR(C17/B17,0) -> 0.70968113 | F17: =SUMIFS('Satışlar'!$E$2:$E$2001,'Satışlar'!$F$2:$F$2001,$N$2,'Satışlar'!$D$2:$D$2001,A17) -> 47163.94
A18: Kocaeli | B18: =SUMIFS('Satışlar'!$E$2:$E$2001,'Satışlar'!$F$2:$F$2001,$B$4,'Satışlar'!$D$2:$D$2001,A18) -> 67355.71 | C18: =SUMIFS('Banka Dökümü'!$C$2:$C$2001,'Banka Dökümü'!$E$2:$E$2001,$B$4,'Banka Dökümü'!$G$2:$G$2001,A18,'Banka Dökümü'!$H$2:$H$2001,"Eşleşti") -> 48677.4 | D18: =B18-C18 -> 18678.31 | E18: =IFERROR(C18/B18,0) -> 0.72269151 | F18: =SUMIFS('Satışlar'!$E$2:$E$2001,'Satışlar'!$F$2:$F$2001,$N$2,'Satışlar'!$D$2:$D$2001,A18) -> 42899.3
A19: Sakarya | B19: =SUMIFS('Satışlar'!$E$2:$E$2001,'Satışlar'!$F$2:$F$2001,$B$4,'Satışlar'!$D$2:$D$2001,A19) -> 64793.94 | C19: =SUMIFS('Banka Dökümü'!$C$2:$C$2001,'Banka Dökümü'!$E$2:$E$2001,$B$4,'Banka Dökümü'!$G$2:$G$2001,A19,'Banka Dökümü'!$H$2:$H$2001,"Eşleşti") -> 47941.47 | D19: =B19-C19 -> 16852.47 | E19: =IFERROR(C19/B19,0) -> 0.73990669 | F19: =SUMIFS('Satışlar'!$E$2:$E$2001,'Satışlar'!$F$2:$F$2001,$N$2,'Satışlar'!$D$2:$D$2001,A19) -> 77568.15
A20: Kayseri | B20: =SUMIFS('Satışlar'!$E$2:$E$2001,'Satışlar'!$F$2:$F$2001,$B$4,'Satışlar'!$D$2:$D$2001,A20) -> 58973.24 | C20: =SUMIFS('Banka Dökümü'!$C$2:$C$2001,'Banka Dökümü'!$E$2:$E$2001,$B$4,'Banka Dökümü'!$G$2:$G$2001,A20,'Banka Dökümü'!$H$2:$H$2001,"Eşleşti") -> 44972.17 | D20: =B20-C20 -> 14001.07 | E20: =IFERROR(C20/B20,0) -> 0.76258605 | F20: =SUMIFS('Satışlar'!$E$2:$E$2001,'Satışlar'!$F$2:$F$2001,$N$2,'Satışlar'!$D$2:$D$2001,A20) -> 58765.88
A21: Gaziantep | B21: =SUMIFS('Satışlar'!$E$2:$E$2001,'Satışlar'!$F$2:$F$2001,$B$4,'Satışlar'!$D$2:$D$2001,A21) -> 71867.79 | C21: =SUMIFS('Banka Dökümü'!$C$2:$C$2001,'Banka Dökümü'!$E$2:$E$2001,$B$4,'Banka Dökümü'!$G$2:$G$2001,A21,'Banka Dökümü'!$H$2:$H$2001,"Eşleşti") -> 56759.16 | D21: =B21-C21 -> 15108.63 | E21: =IFERROR(C21/B21,0) -> 0.78977189 | F21: =SUMIFS('Satışlar'!$E$2:$E$2001,'Satışlar'!$F$2:$F$2001,$N$2,'Satışlar'!$D$2:$D$2001,A21) -> 76101.02
A22: TOPLAM | B22: =SUM(B12:B21) -> 776624.32 | C22: =SUM(C12:C21) -> 568161.01 | D22: =SUM(D12:D21) -> 208463.31 | E22: =IFERROR(C22/B22,0) -> 0.73157767 | F22: =SUM(F12:F21) -> 779926.7
A24: =IF($N$4=0,"Eşleşmeyen ödeme yok → Eşleştirme sayfası","Eşleşmeyen "&$N$4&" ödeme var → Eşleştirme sayfası") -> Eşleşmeyen 3 ödeme var → Eşleştirme sayfası
A25: Sabit il sırası · Satış çubukları büyüklüğü gösterir · Eşleşmeyen girişler tahsilata dahil değildir.
A26: Alacak yalnız seçilen ayın farkıdır; önceki dönem devri, vade ve fatura bazlı kapama bu taslakta yoktur.

Sheet Banka Dökümü
A1: Tarih | B1: Açıklama | C1: Tutar | D1: Bakiye | E1: Ay | F1: Bulunan müşteri | G1: İl | H1: Durum | I1: İnceleme sırası
A2: 46267 | B2: HAVALE KURGUSAL KORALIN MARKET / MAL BEDELI | C2: 16855.08 | D2: 261855.08 | E2: =IF(A2="","",YEAR(A2)&"-"&RIGHT("0"&MONTH(A2),2)) -> 2026-09 | F2: =IF(OR(A2="",B2="",C2<=0),"",IF(SUMPRODUCT(('Müşteriler'!$B$2:$B$101<>"")*ISNUMBER(SEARCH('Müşteriler'!$B$2:$B$101,B2)))=1,IFERROR(INDEX('Müşteriler'!$A$2:$A$101,SUMPRODUCT(('Müşteriler'!$B$2:$B$101<>"")*ISNUMBER(SEARCH('Müşteriler'!$B$2:$B$101,B2)),ROW('Müşteriler'!$B$2:$B$101)-ROW('Müşteriler'!$B$2)+1)),""),"")) -> Koralin Market Örnek İşletme | G2: =IF(F2="","",IFERROR(INDEX('Müşteriler'!$C$2:$C$101,MATCH(F2,'Müşteriler'!$A$2:$A$101,0)),"")) -> Kocaeli | H2: =IF(A2="","",IF(C2<=0,"Satış dışı",IF(OR(F2="",G2=""),"Eşleşmedi","Eşleşti"))) -> Eşleşti | I2: =0+IF(AND(H2="Eşleşmedi",E2='Panel'!$B$4),1,0) -> 0
A3: 46268 | B3: EFT - GONDEREN: KURGUSAL MAVIDAL GIDA - CARI HESAP | C3: 4923.37 | D3: 266778.45 | E3: =IF(A3="","",YEAR(A3)&"-"&RIGHT("0"&MONTH(A3),2)) -> 2026-09 | F3: =IF(OR(A3="",B3="",C3<=0),"",IF(SUMPRODUCT(('Müşteriler'!$B$2:$B$101<>"")*ISNUMBER(SEARCH('Müşteriler'!$B$2:$B$101,B3)))=1,IFERROR(INDEX('Müşteriler'!$A$2:$A$101,SUMPRODUCT(('Müşteriler'!$B$2:$B$101<>"")*ISNUMBER(SEARCH('Müşteriler'!$B$2:$B$101,B3)),ROW('Müşteriler'!$B$2:$B$101)-ROW('Müşteriler'!$B$2)+1)),""),"")) -> Mavidal Gıda Örnek İşletme | G3: =IF(F3="","",IFERROR(INDEX('Müşteriler'!$C$2:$C$101,MATCH(F3,'Müşteriler'!$A$2:$A$101,0)),"")) -> İstanbul | H3: =IF(A3="","",IF(C3<=0,"Satış dışı",IF(OR(F3="",G3=""),"Eşleşmedi","Eşleşti"))) -> Eşleşti | I3: =I2+IF(AND(H3="Eşleşmedi",E3='Panel'!$B$4),1,0) -> 0
A4: 46268 | B4: EFT - GONDEREN: KURGUSAL ZEROVA TEDARIK - CARI HESAP | C4: 7088.7 | D4: 273867.15 | E4: =IF(A4="","",YEAR(A4)&"-"&RIGHT("0"&MONTH(A4),2)) -> 2026-09 | F4: =IF(OR(A4="",B4="",C4<=0),"",IF(SUMPRODUCT(('Müşteriler'!$B$2:$B$101<>"")*ISNUMBER(SEARCH('Müşteriler'!$B$2:$B$101,B4)))=1,IFERROR(INDEX('Müşteriler'!$A$2:$A$101,SUMPRODUCT(('Müşteriler'!$B$2:$B$101<>"")*ISNUMBER(SEARCH('Müşteriler'!$B$2:$B$101,B4)),ROW('Müşteriler'!$B$2:$B$101)-ROW('Müşteriler'!$B$2)+1)),""),"")) -> Zerova Tedarik Örnek İşletme | G4: =IF(F4="","",IFERROR(INDEX('Müşteriler'!$C$2:$C$101,MATCH(F4,'Müşteriler'!$A$2:$A$101,0)),"")) -> Sakarya | H4: =IF(A4="","",IF(C4<=0,"Satış dışı",IF(OR(F4="",G4=""),"Eşleşmedi","Eşleşti"))) -> Eşleşti | I4: =I3+IF(AND(H4="Eşleşmedi",E4='Panel'!$B$4),1,0) -> 0
A5: 46269 | B5: FAST GELEN - KURGUSAL GOLVERA DAGITIM / FATURA ODEMESI | C5: 28142.08 | D5: 302009.23 | E5: =IF(A5="","",YEAR(A5)&"-"&RIGHT("0"&MONTH(A5),2)) -> 2026-09 | F5: =IF(OR(A5="",B5="",C5<=0),"",IF(SUMPRODUCT(('Müşteriler'!$B$2:$B$101<>"")*ISNUMBER(SEARCH('Müşteriler'!$B$2:$B$101,B5)))=1,IFERROR(INDEX('Müşteriler'!$A$2:$A$101,SUMPRODUCT(('Müşteriler'!$B$2:$B$101<>"")*ISNUMBER(SEARCH('Müşteriler'!$B$2:$B$101,B5)),ROW('Müşteriler'!$B$2:$B$101)-ROW('Müşteriler'!$B$2)+1)),""),"")) -> Gölvera Dağıtım Örnek İşletme | G5: =IF(F5="","",IFERROR(INDEX('Müşteriler'!$C$2:$C$101,MATCH(F5,'Müşteriler'!$A$2:$A$101,0)),"")) -> Kayseri | H5: =IF(A5="","",IF(C5<=0,"Satış dışı",IF(OR(F5="",G5=""),"Eşleşmedi","Eşleşti"))) -> Eşleşti | I5: =I4+IF(AND(H5="Eşleşmedi",E5='Panel'!$B$4),1,0) -> 0
A6: 46269 | B6: FAST GELEN - KURGUSAL MORCATI TEDARIK / FATURA ODEMESI | C6: 9673.91 | D6: 311683.14 | E6: =IF(A6="","",YEAR(A6)&"-"&RIGHT("0"&MONTH(A6),2)) -> 2026-09 | F6: =IF(OR(A6="",B6="",C6<=0),"",IF(SUMPRODUCT(('Müşteriler'!$B$2:$B$101<>"")*ISNUMBER(SEARCH('Müşteriler'!$B$2:$B$101,B6)))=1,IFERROR(INDEX('Müşteriler'!$A$2:$A$101,SUMPRODUCT(('Müşteriler'!$B$2:$B$101<>"")*ISNUMBER(SEARCH('Müşteriler'!$B$2:$B$101,B6)),ROW('Müşteriler'!$B$2:$B$101)-ROW('Müşteriler'!$B$2)+1)),""),"")) -> Morçatı Tedarik Örnek İşletme | G6: =IF(F6="","",IFERROR(INDEX('Müşteriler'!$C$2:$C$101,MATCH(F6,'Müşteriler'!$A$2:$A$101,0)),"")) -> Sakarya | H6: =IF(A6="","",IF(C6<=0,"Satış dışı",IF(OR(F6="",G6=""),"Eşleşmedi","Eşleşti"))) -> Eşleşti | I6: =I5+IF(AND(H6="Eşleşmedi",E6='Panel'!$B$4),1,0) -> 0
A7: 46269 | B7: FAST GELEN - KURGUSAL YAPRIVA TICARET / FATURA ODEMESI | C7: 37130.68 | D7: 348813.82 | E7: =IF(A7="","",YEAR(A7)&"-"&RIGHT("0"&MONTH(A7),2)) -> 2026-09 | F7: =IF(OR(A7="",B7="",C7<=0),"",IF(SUMPRODUCT(('Müşteriler'!$B$2:$B$101<>"")*ISNUMBER(SEARCH('Müşteriler'!$B$2:$B$101,B7)))=1,IFERROR(INDEX('Müşteriler'!$A$2:$A$101,SUMPRODUCT(('Müşteriler'!$B$2:$B$101<>"")*ISNUMBER(SEARCH('Müşteriler'!$B$2:$B$101,B7)),ROW('Müşteriler'!$B$2:$B$101)-ROW('Müşteriler'!$B$2)+1)),""),"")) -> Yapriva Ticaret Örnek İşletme | G7: =IF(F7="","",IFERROR(INDEX('Müşteriler'!$C$2:$C$101,MATCH(F7,'Müşteriler'!$A$2:$A$101,0)),"")) -> Antalya | H7: =IF(A7="","",IF(C7<=0,"Satış dışı",IF(OR(F7="",G7=""),"Eşleşmedi","Eşleşti"))) -> Eşleşti | I7: =I6+IF(AND(H7="Eşleşmedi",E7='Panel'!$B$4),1,0) -> 0
A8: 46269 | B8: HAVALE KURGUSAL DUSOVA MARKET / MAL BEDELI | C8: 14423.37 | D8: 363237.19 | E8: =IF(A8="","",YEAR(A8)&"-"&RIGHT("0"&MONTH(A8),2)) -> 2026-09 | F8: =IF(OR(A8="",B8="",C8<=0),"",IF(SUMPRODUCT(('Müşteriler'!$B$2:$B$101<>"")*ISNUMBER(SEARCH('Müşteriler'!$B$2:$B$101,B8)))=1,IFERROR(INDEX('Müşteriler'!$A$2:$A$101,SUMPRODUCT(('Müşteriler'!$B$2:$B$101<>"")*ISNUMBER(SEARCH('Müşteriler'!$B$2:$B$101,B8)),ROW('Müşteriler'!$B$2:$B$101)-ROW('Müşteriler'!$B$2)+1)),""),"")) -> Düşova Market Örnek İşletme | G8: =IF(F8="","",IFERROR(INDEX('Müşteriler'!$C$2:$C$101,MATCH(F8,'Müşteriler'!$A$2:$A$101,0)),"")) -> Ankara | H8: =IF(A8="","",IF(C8<=0,"Satış dışı",IF(OR(F8="",G8=""),"Eşleşmedi","Eşleşti"))) -> Eşleşti | I8: =I7+IF(AND(H8="Eşleşmedi",E8='Panel'!$B$4),1,0) -> 0
A9: 46270 | B9: EFT ISLEM UCRETI / BANKA MASRAFI | C9: -28.5 | D9: 363208.69 | E9: =IF(A9="","",YEAR(A9)&"-"&RIGHT("0"&MONTH(A9),2)) -> 2026-09 | F9: =IF(OR(A9="",B9="",C9<=0),"",IF(SUMPRODUCT(('Müşteriler'!$B$2:$B$101<>"")*ISNUMBER(SEARCH('Müşteriler'!$B$2:$B$101,B9)))=1,IFERROR(INDEX('Müşteriler'!$A$2:$A$101,SUMPRODUCT(('Müşteriler'!$B$2:$B$101<>"")*ISNUMBER(SEARCH('Müşteriler'!$B$2:$B$101,B9)),ROW('Müşteriler'!$B$2:$B$101)-ROW('Müşteriler'!$B$2)+1)),""),"")) | G9: =IF(F9="","",IFERROR(INDEX('Müşteriler'!$C$2:$C$101,MATCH(F9,'Müşteriler'!$A$2:$A$101,0)),"")) | H9: =IF(A9="","",IF(C9<=0,"Satış dışı",IF(OR(F9="",G9=""),"Eşleşmedi","Eşleşti"))) -> Satış dışı | I9: =I8+IF(AND(H9="Eşleşmedi",E9='Panel'!$B$4),1,0) -> 0
A10: 46270 | B10: FAST GELEN - KURGUSAL AYVENK TICARET / FATURA ODEMESI | C10: 8550.74 | D10: 371759.43 | E10: =IF(A10="","",YEAR(A10)&"-"&RIGHT("0"&MONTH(A10),2)) -> 2026-09 | F10: =IF(OR(A10="",B10="",C10<=0),"",IF(SUMPRODUCT(('Müşteriler'!$B$2:$B$101<>"")*ISNUMBER(SEARCH('Müşteriler'!$B$2:$B$101,B10)))=1,IFERROR(INDEX('Müşteriler'!$A$2:$A$101,SUMPRODUCT(('Müşteriler'!$B$2:$B$101<>"")*ISNUMBER(SEARCH('Müşteriler'!$B$2:$B$101,B10)),ROW('Müşteriler'!$B$2:$B$101)-ROW('Müşteriler'!$B$2)+1)),""),"")) -> Ayvenk Ticaret Örnek İşletme | G10: =IF(F10="","",IFERROR(INDEX('Müşteriler'!$C$2:$C$101,MATCH(F10,'Müşteriler'!$A$2:$A$101,0)),"")) -> Antalya | H10: =IF(A10="","",IF(C10<=0,"Satış dışı",IF(OR(F10="",G10=""),"Eşleşmedi","Eşleşti"))) -> Eşleşti | I10: =I9+IF(AND(H10="Eşleşmedi",E10='Panel'!$B$4),1,0) -> 0
A11: 46270 | B11: HAVALE KURGUSAL MAVIDAL GIDA / MAL BEDELI | C11: 4923.37 | D11: 376682.8 | E11: =IF(A11="","",YEAR(A11)&"-"&RIGHT("0"&MONTH(A11),2)) -> 2026-09 | F11: =IF(OR(A11="",B11="",C11<=0),"",IF(SUMPRODUCT(('Müşteriler'!$B$2:$B$101<>"")*ISNUMBER(SEARCH('Müşteriler'!$B$2:$B$101,B11)))=1,IFERROR(INDEX('Müşteriler'!$A$2:$A$101,SUMPRODUCT(('Müşteriler'!$B$2:$B$101<>"")*ISNUMBER(SEARCH('Müşteriler'!$B$2:$B$101,B11)),ROW('Müşteriler'!$B$2:$B$101)-ROW('Müşteriler'!$B$2)+1)),""),"")) -> Mavidal Gıda Örnek İşletme | G11: =IF(F11="","",IFERROR(INDEX('Müşteriler'!$C$2:$C$101,MATCH(F11,'Müşteriler'!$A$2:$A$101,0)),"")) -> İstanbul | H11: =IF(A11="","",IF(C11<=0,"Satış dışı",IF(OR(F11="",G11=""),"Eşleşmedi","Eşleşti"))) -> Eşleşti | I11: =I10+IF(AND(H11="Eşleşmedi",E11='Panel'!$B$4),1,0) -> 0
A12: 46271 | B12: EFT - GONDEREN: KURGUSAL TANYUVA GIDA - CARI HESAP | C12: 6748.46 | D12: 383431.26 | E12: =IF(A12="","",YEAR(A12)&"-"&RIGHT("0"&MONTH(A12),2)) -> 2026-09 | F12: =IF(OR(A12="",B12="",C12<=0),"",IF(SUMPRODUCT(('Müşteriler'!$B$2:$B$101<>"")*ISNUMBER(SEARCH('Müşteriler'!$B$2:$B$101,B12)))=1,IFERROR(INDEX('Müşteriler'!$A$2:$A$101,SUMPRODUCT(('Müşteriler'!$B$2:$B$101<>"")*ISNUMBER(SEARCH('Müşteriler'!$B$2:$B$101,B12)),ROW('Müşteriler'!$B$2:$B$101)-ROW('Müşteriler'!$B$2)+1)),""),"")) -> Tanyuva Gıda Örnek İşletme | G12: =IF(F12="","",IFERROR(INDEX('Müşteriler'!$C$2:$C$101,MATCH(F12,'Müşteriler'!$A$2:$A$101,0)),"")) -> İstanbul | H12: =IF(A12="","",IF(C12<=0,"Satış dışı",IF(OR(F12="",G12=""),"Eşleşmedi","Eşleşti"))) -> Eşleşti | I12: =I11+IF(AND(H12="Eşleşmedi",E12='Panel'!$B$4),1,0) -> 0
A13: 46272 | B13: EFT - GONDEREN: KURGUSAL CISENTA TICARET - CARI HESAP | C13: 8060.99 | D13: 391492.25 | E13: =IF(A13="","",YEAR(A13)&"-"&RIGHT("0"&MONTH(A13),2)) -> 2026-09 | F13: =IF(OR(A13="",B13="",C13<=0),"",IF(SUMPRODUCT(('Müşteriler'!$B$2:$B$101<>"")*ISNUMBER(SEARCH('Müşteriler'!$B$2:$B$101,B13)))=1,IFERROR(INDEX('Müşteriler'!$A$2:$A$101,SUMPRODUCT(('Müşteriler'!$B$2:$B$101<>"")*ISNUMBER(SEARCH('Müşteriler'!$B$2:$B$101,B13)),ROW('Müşteriler'!$B$2:$B$101)-ROW('Müşteriler'!$B$2)+1)),""),"")) -> Çisenta Ticaret Örnek İşletme | G13: =IF(F13="","",IFERROR(INDEX('Müşteriler'!$C$2:$C$101,MATCH(F13,'Müşteriler'!$A$2:$A$101,0)),"")) -> Antalya | H13: =IF(A13="","",IF(C13<=0,"Satış dışı",IF(OR(F13="",G13=""),"Eşleşmedi","Eşleşti"))) -> Eşleşti | I13: =I12+IF(AND(H13="Eşleşmedi",E13='Panel'!$B$4),1,0) -> 0
A14: 46273 | B14: EFT - GONDEREN: KURGUSAL BULUTIZ MARKET - CARI HESAP | C14: 9448.98 | D14: 400941.23 | E14: =IF(A14="","",YEAR(A14)&"-"&RIGHT("0"&MONTH(A14),2)) -> 2026-09 | F14: =IF(OR(A14="",B14="",C14<=0),"",IF(SUMPRODUCT(('Müşteriler'!$B$2:$B$101<>"")*ISNUMBER(SEARCH('Müşteriler'!$B$2:$B$101,B14)))=1,IFERROR(INDEX('Müşteriler'!$A$2:$A$101,SUMPRODUCT(('Müşteriler'!$B$2:$B$101<>"")*ISNUMBER(SEARCH('Müşteriler'!$B$2:$B$101,B14)),ROW('Müşteriler'!$B$2:$B$101)-ROW('Müşteriler'!$B$2)+1)),""),"")) -> Bulutiz Market Örnek İşletme | G14: =IF(F14="","",IFERROR(INDEX('Müşteriler'!$C$2:$C$101,MATCH(F14,'Müşteriler'!$A$2:$A$101,0)),"")) -> Ankara | H14: =IF(A14="","",IF(C14<=0,"Satış dışı",IF(OR(F14="",G14=""),"Eşleşmedi","Eşleşti"))) -> Eşleşti | I14: =I13+IF(AND(H14="Eşleşmedi",E14='Panel'!$B$4),1,0) -> 0
... A111: 46323 | B111: HAVALE KURGUSAL DENIZOVA GIDA / MAL BEDELI | C111: 5185.12 | D111: 1326976.2 | E111: =IF(A111="","",YEAR(A111)&"-"&RIGHT("0"&MONTH(A111),2)) -> 2026-10 | F111: =IF(OR(A111="",B111="",C111<=0),"",IF(SUMPRODUCT(('Müşteriler'!$B$2:$B$101<>"")*ISNUMBER(SEARCH('Müşteriler'!$B$2:$B$101,B111)))=1,IFERROR(INDEX('Müşteriler'!$A$2:$A$101,SUMPRODUCT(('Müşteriler'!$B$2:$B$101<>"")*ISNUMBER(SEARCH('Müşteriler'!$B$2:$B$101,B111)),ROW('Müşteriler'!$B$2:$B$101)-ROW('Müşteriler'!$B$2)+1)),""),"")) -> Denizova Gıda Örnek İşletme | G111: =IF(F111="","",IFERROR(INDEX('Müşteriler'!$C$2:$C$101,MATCH(F111,'Müşteriler'!$A$2:$A$101,0)),"")) -> Konya | H111: =IF(A111="","",IF(C111<=0,"Satış dışı",IF(OR(F111="",G111=""),"Eşleşmedi","Eşleşti"))) -> Eşleşti | I111: =I110+IF(AND(H111="Eşleşmedi",E111='Panel'!$B$4),1,0) -> 3
E112: =IF(A112="","",YEAR(A112)&"-"&RIGHT("0"&MONTH(A112),2)) | F112: =IF(OR(A112="",B112="",C112<=0),"",IF(SUMPRODUCT(('Müşteriler'!$B$2:$B$101<>"")*ISNUMBER(SEARCH('Müşteriler'!$B$2:$B$101,B112)))=1,IFERROR(INDEX('Müşteriler'!$A$2:$A$101,SUMPRODUCT(('Müşteriler'!$B$2:$B$101<>"")*ISNUMBER(SEARCH('Müşteriler'!$B$2:$B$101,B112)),ROW('Müşteriler'!$B$2:$B$101)-ROW('Müşteriler'!$B$2)+1)),""),"")) | G112: =IF(F112="","",IFERROR(INDEX('Müşteriler'!$C$2:$C$101,MATCH(F112,'Müşteriler'!$A$2:$A$101,0)),"")) | H112: =IF(A112="","",IF(C112<=0,"Satış dışı",IF(OR(F112="",G112=""),"Eşleşmedi","Eşleşti"))) | I112: =I111+IF(AND(H112="Eşleşmedi",E112='Panel'!$B$4),1,0) -> 3
E113: =IF(A113="","",YEAR(A113)&"-"&RIGHT("0"&MONTH(A113),2)) | F113: =IF(OR(A113="",B113="",C113<=0),"",IF(SUMPRODUCT(('Müşteriler'!$B$2:$B$101<>"")*ISNUMBER(SEARCH('Müşteriler'!$B$2:$B$101,B113)))=1,IFERROR(INDEX('Müşteriler'!$A$2:$A$101,SUMPRODUCT(('Müşteriler'!$B$2:$B$101<>"")*ISNUMBER(SEARCH('Müşteriler'!$B$2:$B$101,B113)),ROW('Müşteriler'!$B$2:$B$101)-ROW('Müşteriler'!$B$2)+1)),""),"")) | G113: =IF(F113="","",IFERROR(INDEX('Müşteriler'!$C$2:$C$101,MATCH(F113,'Müşteriler'!$A$2:$A$101,0)),"")) | H113: =IF(A113="","",IF(C113<=0,"Satış dışı",IF(OR(F113="",G113=""),"Eşleşmedi","Eşleşti"))) | I113: =I112+IF(AND(H113="Eşleşmedi",E113='Panel'!$B$4),1,0) -> 3
E114: =IF(A114="","",YEAR(A114)&"-"&RIGHT("0"&MONTH(A114),2)) | F114: =IF(OR(A114="",B114="",C114<=0),"",IF(SUMPRODUCT(('Müşteriler'!$B$2:$B$101<>"")*ISNUMBER(SEARCH('Müşteriler'!$B$2:$B$101,B114)))=1,IFERROR(INDEX('Müşteriler'!$A$2:$A$101,SUMPRODUCT(('Müşteriler'!$B$2:$B$101<>"")*ISNUMBER(SEARCH('Müşteriler'!$B$2:$B$101,B114)),ROW('Müşteriler'!$B$2:$B$101)-ROW('Müşteriler'!$B$2)+1)),""),"")) | G114: =IF(F114="","",IFERROR(INDEX('Müşteriler'!$C$2:$C$101,MATCH(F114,'Müşteriler'!$A$2:$A$101,0)),"")) | H114: =IF(A114="","",IF(C114<=0,"Satış dışı",IF(OR(F114="",G114=""),"Eşleşmedi","Eşleşti"))) | I114: =I113+IF(AND(H114="Eşleşmedi",E114='Panel'!$B$4),1,0) -> 3
E115: =IF(A115="","",YEAR(A115)&"-"&RIGHT("0"&MONTH(A115),2)) | F115: =IF(OR(A115="",B115="",C115<=0),"",IF(SUMPRODUCT(('Müşteriler'!$B$2:$B$101<>"")*ISNUMBER(SEARCH('Müşteriler'!$B$2:$B$101,B115)))=1,IFERROR(INDEX('Müşteriler'!$A$2:$A$101,SUMPRODUCT(('Müşteriler'!$B$2:$B$101<>"")*ISNUMBER(SEARCH('Müşteriler'!$B$2:$B$101,B115)),ROW('Müşteriler'!$B$2:$B$101)-ROW('Müşteriler'!$B$2)+1)),""),"")) | G115: =IF(F115="","",IFERROR(INDEX('Müşteriler'!$C$2:$C$101,MATCH(F115,'Müşteriler'!$A$2:$A$101,0)),"")) | H115: =IF(A115="","",IF(C115<=0,"Satış dışı",IF(OR(F115="",G115=""),"Eşleşmedi","Eşleşti"))) | I115: =I114+IF(AND(H115="Eşleşmedi",E115='Panel'!$B$4),1,0) -> 3
E116: =IF(A116="","",YEAR(A116)&"-"&RIGHT("0"&MONTH(A116),2)) | F116: =IF(OR(A116="",B116="",C116<=0),"",IF(SUMPRODUCT(('Müşteriler'!$B$2:$B$101<>"")*ISNUMBER(SEARCH('Müşteriler'!$B$2:$B$101,B116)))=1,IFERROR(INDEX('Müşteriler'!$A$2:$A$101,SUMPRODUCT(('Müşteriler'!$B$2:$B$101<>"")*ISNUMBER(SEARCH('Müşteriler'!$B$2:$B$101,B116)),ROW('Müşteriler'!$B$2:$B$101)-ROW('Müşteriler'!$B$2)+1)),""),"")) | G116: =IF(F116="","",IFERROR(INDEX('Müşteriler'!$C$2:$C$101,MATCH(F116,'Müşteriler'!$A$2:$A$101,0)),"")) | H116: =IF(A116="","",IF(C116<=0,"Satış dışı",IF(OR(F116="",G116=""),"Eşleşmedi","Eşleşti"))) | I116: =I115+IF(AND(H116="Eşleşmedi",E116='Panel'!$B$4),1,0) -> 3
E117: =IF(A117="","",YEAR(A117)&"-"&RIGHT("0"&MONTH(A117),2)) | F117: =IF(OR(A117="",B117="",C117<=0),"",IF(SUMPRODUCT(('Müşteriler'!$B$2:$B$101<>"")*ISNUMBER(SEARCH('Müşteriler'!$B$2:$B$101,B117)))=1,IFERROR(INDEX('Müşteriler'!$A$2:$A$101,SUMPRODUCT(('Müşteriler'!$B$2:$B$101<>"")*ISNUMBER(SEARCH('Müşteriler'!$B$2:$B$101,B117)),ROW('Müşteriler'!$B$2:$B$101)-ROW('Müşteriler'!$B$2)+1)),""),"")) | G117: =IF(F117="","",IFERROR(INDEX('Müşteriler'!$C$2:$C$101,MATCH(F117,'Müşteriler'!$A$2:$A$101,0)),"")) | H117: =IF(A117="","",IF(C117<=0,"Satış dışı",IF(OR(F117="",G117=""),"Eşleşmedi","Eşleşti"))) | I117: =I116+IF(AND(H117="Eşleşmedi",E117='Panel'!$B$4),1,0) -> 3
E118: =IF(A118="","",YEAR(A118)&"-"&RIGHT("0"&MONTH(A118),2)) | F118: =IF(OR(A118="",B118="",C118<=0),"",IF(SUMPRODUCT(('Müşteriler'!$B$2:$B$101<>"")*ISNUMBER(SEARCH('Müşteriler'!$B$2:$B$101,B118)))=1,IFERROR(INDEX('Müşteriler'!$A$2:$A$101,SUMPRODUCT(('Müşteriler'!$B$2:$B$101<>"")*ISNUMBER(SEARCH('Müşteriler'!$B$2:$B$101,B118)),ROW('Müşteriler'!$B$2:$B$101)-ROW('Müşteriler'!$B$2)+1)),""),"")) | G118: =IF(F118="","",IFERROR(INDEX('Müşteriler'!$C$2:$C$101,MATCH(F118,'Müşteriler'!$A$2:$A$101,0)),"")) | H118: =IF(A118="","",IF(C118<=0,"Satış dışı",IF(OR(F118="",G118=""),"Eşleşmedi","Eşleşti"))) | I118: =I117+IF(AND(H118="Eşleşmedi",E118='Panel'!$B$4),1,0) -> 3
E119: =IF(A119="","",YEAR(A119)&"-"&RIGHT("0"&MONTH(A119),2)) | F119: =IF(OR(A119="",B119="",C119<=0),"",IF(SUMPRODUCT(('Müşteriler'!$B$2:$B$101<>"")*ISNUMBER(SEARCH('Müşteriler'!$B$2:$B$101,B119)))=1,IFERROR(INDEX('Müşteriler'!$A$2:$A$101,SUMPRODUCT(('Müşteriler'!$B$2:$B$101<>"")*ISNUMBER(SEARCH('Müşteriler'!$B$2:$B$101,B119)),ROW('Müşteriler'!$B$2:$B$101)-ROW('Müşteriler'!$B$2)+1)),""),"")) | G119: =IF(F119="","",IFERROR(INDEX('Müşteriler'!$C$2:$C$101,MATCH(F119,'Müşteriler'!$A$2:$A$101,0)),"")) | H119: =IF(A119="","",IF(C119<=0,"Satış dışı",IF(OR(F119="",G119=""),"Eşleşmedi","Eşleşti"))) | I119: =I118+IF(AND(H119="Eşleşmedi",E119='Panel'!$B$4),1,0) -> 3
E120: =IF(A120="","",YEAR(A120)&"-"&RIGHT("0"&MONTH(A120),2)) | F120: =IF(OR(A120="",B120="",C120<=0),"",IF(SUMPRODUCT(('Müşteriler'!$B$2:$B$101<>"")*ISNUMBER(SEARCH('Müşteriler'!$B$2:$B$101,B120)))=1,IFERROR(INDEX('Müşteriler'!$A$2:$A$101,SUMPRODUCT(('Müşteriler'!$B$2:$B$101<>"")*ISNUMBER(SEARCH('Müşteriler'!$B$2:$B$101,B120)),ROW('Müşteriler'!$B$2:$B$101)-ROW('Müşteriler'!$B$2)+1)),""),"")) | G120: =IF(F120="","",IFERROR(INDEX('Müşteriler'!$C$2:$C$101,MATCH(F120,'Müşteriler'!$A$2:$A$101,0)),"")) | H120: =IF(A120="","",IF(C120<=0,"Satış dışı",IF(OR(F120="",G120=""),"Eşleşmedi","Eşleşti"))) | I120: =I119+IF(AND(H120="Eşleşmedi",E120='Panel'!$B$4),1,0) -> 3
E121: =IF(A121="","",YEAR(A121)&"-"&RIGHT("0"&MONTH(A121),2)) | F121: =IF(OR(A121="",B121="",C121<=0),"",IF(SUMPRODUCT(('Müşteriler'!$B$2:$B$101<>"")*ISNUMBER(SEARCH('Müşteriler'!$B$2:$B$101,B121)))=1,IFERROR(INDEX('Müşteriler'!$A$2:$A$101,SUMPRODUCT(('Müşteriler'!$B$2:$B$101<>"")*ISNUMBER(SEARCH('Müşteriler'!$B$2:$B$101,B121)),ROW('Müşteriler'!$B$2:$B$101)-ROW('Müşteriler'!$B$2)+1)),""),"")) | G121: =IF(F121="","",IFERROR(INDEX('Müşteriler'!$C$2:$C$101,MATCH(F121,'Müşteriler'!$A$2:$A$101,0)),"")) | H121: =IF(A121="","",IF(C121<=0,"Satış dışı",IF(OR(F121="",G121=""),"Eşleşmedi","Eşleşti"))) | I121: =I120+IF(AND(H121="Eşleşmedi",E121='Panel'!$B$4),1,0) -> 3
E122: =IF(A122="","",YEAR(A122)&"-"&RIGHT("0"&MONTH(A122),2)) | F122: =IF(OR(A122="",B122="",C122<=0),"",IF(SUMPRODUCT(('Müşteriler'!$B$2:$B$101<>"")*ISNUMBER(SEARCH('Müşteriler'!$B$2:$B$101,B122)))=1,IFERROR(INDEX('Müşteriler'!$A$2:$A$101,SUMPRODUCT(('Müşteriler'!$B$2:$B$101<>"")*ISNUMBER(SEARCH('Müşteriler'!$B$2:$B$101,B122)),ROW('Müşteriler'!$B$2:$B$101)-ROW('Müşteriler'!$B$2)+1)),""),"")) | G122: =IF(F122="","",IFERROR(INDEX('Müşteriler'!$C$2:$C$101,MATCH(F122,'Müşteriler'!$A$2:$A$101,0)),"")) | H122: =IF(A122="","",IF(C122<=0,"Satış dışı",IF(OR(F122="",G122=""),"Eşleşmedi","Eşleşti"))) | I122: =I121+IF(AND(H122="Eşleşmedi",E122='Panel'!$B$4),1,0) -> 3
E123: =IF(A123="","",YEAR(A123)&"-"&RIGHT("0"&MONTH(A123),2)) | F123: =IF(OR(A123="",B123="",C123<=0),"",IF(SUMPRODUCT(('Müşteriler'!$B$2:$B$101<>"")*ISNUMBER(SEARCH('Müşteriler'!$B$2:$B$101,B123)))=1,IFERROR(INDEX('Müşteriler'!$A$2:$A$101,SUMPRODUCT(('Müşteriler'!$B$2:$B$101<>"")*ISNUMBER(SEARCH('Müşteriler'!$B$2:$B$101,B123)),ROW('Müşteriler'!$B$2:$B$101)-ROW('Müşteriler'!$B$2)+1)),""),"")) | G123: =IF(F123="","",IFERROR(INDEX('Müşteriler'!$C$2:$C$101,MATCH(F123,'Müşteriler'!$A$2:$A$101,0)),"")) | H123: =IF(A123="","",IF(C123<=0,"Satış dışı",IF(OR(F123="",G123=""),"Eşleşmedi","Eşleşti"))) | I123: =I122+IF(AND(H123="Eşleşmedi",E123='Panel'!$B$4),1,0) -> 3
... E2001: =IF(A2001="","",YEAR(A2001)&"-"&RIGHT("0"&MONTH(A2001),2)) | F2001: =IF(OR(A2001="",B2001="",C2001<=0),"",IF(SUMPRODUCT(('Müşteriler'!$B$2:$B$101<>"")*ISNUMBER(SEARCH('Müşteriler'!$B$2:$B$101,B2001)))=1,IFERROR(INDEX('Müşteriler'!$A$2:$A$101,SUMPRODUCT(('Müşteriler'!$B$2:$B$101<>"")*ISNUMBER(SEARCH('Müşteriler'!$B$2:$B$101,B2001)),ROW('Müşteriler'!$B$2:$B$101)-ROW('Müşteriler'!$B$2)+1)),""),"")) | G2001: =IF(F2001="","",IFERROR(INDEX('Müşteriler'!$C$2:$C$101,MATCH(F2001,'Müşteriler'!$A$2:$A$101,0)),"")) | H2001: =IF(A2001="","",IF(C2001<=0,"Satış dışı",IF(OR(F2001="",G2001=""),"Eşleşmedi","Eşleşti"))) | I2001: =I2000+IF(AND(H2001="Eşleşmedi",E2001='Panel'!$B$4),1,0) -> 3

Sheet Satışlar
A1: Tarih | B1: Fatura no | C1: Müşteri | D1: İl | E1: Tutar | F1: Ay
A2: 46266 | B2: TSL-202609-044 | C2: Ardılyel Dağıtım Örnek İşletme | D2: Kayseri | E2: 6806.84 | F2: =IF(A2="","",YEAR(A2)&"-"&RIGHT("0"&MONTH(A2),2)) -> 2026-09
A3: 46268 | B3: TSL-202609-005 | C3: Ayvenk Ticaret Örnek İşletme | D3: Antalya | E3: 8375.31 | F3: =IF(A3="","",YEAR(A3)&"-"&RIGHT("0"&MONTH(A3),2)) -> 2026-09
A4: 46268 | B4: TSL-202609-036 | C4: Çiyrota Gıda Örnek İşletme | D4: İstanbul | E4: 19445.78 | F4: =IF(A4="","",YEAR(A4)&"-"&RIGHT("0"&MONTH(A4),2)) -> 2026-09
A5: 46268 | B5: TSL-202609-067 | C5: Gölvera Dağıtım Örnek İşletme | D5: Kayseri | E5: 4658.61 | F5: =IF(A5="","",YEAR(A5)&"-"&RIGHT("0"&MONTH(A5),2)) -> 2026-09
A6: 46269 | B6: TSL-202609-013 | C6: Kervola Tedarik Örnek İşletme | D6: İzmir | E6: 9702.37 | F6: =IF(A6="","",YEAR(A6)&"-"&RIGHT("0"&MONTH(A6),2)) -> 2026-09
A7: 46269 | B7: TSL-202609-063 | C7: Ayserin Dağıtım Örnek İşletme | D7: Bursa | E7: 7085.52 | F7: =IF(A7="","",YEAR(A7)&"-"&RIGHT("0"&MONTH(A7),2)) -> 2026-09
A8: 46270 | B8: TSL-202609-016 | C8: Denizova Gıda Örnek İşletme | D8: Konya | E8: 12013.35 | F8: =IF(A8="","",YEAR(A8)&"-"&RIGHT("0"&MONTH(A8),2)) -> 2026-09
A9: 46270 | B9: TSL-202609-049 | C9: Lalrota Dağıtım Örnek İşletme | D9: Bursa | E9: 10314.72 | F9: =IF(A9="","",YEAR(A9)&"-"&RIGHT("0"&MONTH(A9),2)) -> 2026-09
A10: 46271 | B10: TSL-202609-012 | C10: Bulutiz Market Örnek İşletme | D10: Ankara | E10: 5363.46 | F10: =IF(A10="","",YEAR(A10)&"-"&RIGHT("0"&MONTH(A10),2)) -> 2026-09
A11: 46272 | B11: TSL-202609-007 | C11: Yelmino Market Örnek İşletme | D11: Kocaeli | E11: 9123.01 | F11: =IF(A11="","",YEAR(A11)&"-"&RIGHT("0"&MONTH(A11),2)) -> 2026-09
A12: 46272 | B12: TSL-202609-009 | C12: Gölvera Dağıtım Örnek İşletme | D12: Kayseri | E12: 7487.41 | F12: =IF(A12="","",YEAR(A12)&"-"&RIGHT("0"&MONTH(A12),2)) -> 2026-09
A13: 46272 | B13: TSL-202609-065 | C13: Gölvera Dağıtım Örnek İşletme | D13: Kayseri | E13: 7355.47 | F13: =IF(A13="","",YEAR(A13)&"-"&RIGHT("0"&MONTH(A13),2)) -> 2026-09
... A141: 46323 | B141: TSL-202610-056 | C141: Kumvadi Tedarik Örnek İşletme | D141: İzmir | E141: 12993.1 | F141: =IF(A141="","",YEAR(A141)&"-"&RIGHT("0"&MONTH(A141),2)) -> 2026-10
F142: =IF(A142="","",YEAR(A142)&"-"&RIGHT("0"&MONTH(A142),2))
F143: =IF(A143="","",YEAR(A143)&"-"&RIGHT("0"&MONTH(A143),2))
F144: =IF(A144="","",YEAR(A144)&"-"&RIGHT("0"&MONTH(A144),2))
F145: =IF(A145="","",YEAR(A145)&"-"&RIGHT("0"&MONTH(A145),2))
F146: =IF(A146="","",YEAR(A146)&"-"&RIGHT("0"&MONTH(A146),2))
F147: =IF(A147="","",YEAR(A147)&"-"&RIGHT("0"&MONTH(A147),2))
F148: =IF(A148="","",YEAR(A148)&"-"&RIGHT("0"&MONTH(A148),2))
F149: =IF(A149="","",YEAR(A149)&"-"&RIGHT("0"&MONTH(A149),2))
F150: =IF(A150="","",YEAR(A150)&"-"&RIGHT("0"&MONTH(A150),2))
F151: =IF(A151="","",YEAR(A151)&"-"&RIGHT("0"&MONTH(A151),2))
F152: =IF(A152="","",YEAR(A152)&"-"&RIGHT("0"&MONTH(A152),2))
F153: =IF(A153="","",YEAR(A153)&"-"&RIGHT("0"&MONTH(A153),2))
... F2001: =IF(A2001="","",YEAR(A2001)&"-"&RIGHT("0"&MONTH(A2001),2))

Sheet Müşteriler
A1: Müşteri | B1: Aranacak ad | C1: İl | F1: İl listesi | H1: Ay listesi
A2: Mavidal Gıda Örnek İşletme | B2: KURGUSAL MAVIDAL GIDA | C2: İstanbul | F2: İstanbul | H2: 2026-01
A3: Düşova Market Örnek İşletme | B3: KURGUSAL DUSOVA MARKET | C3: Ankara | F3: Ankara | H3: 2026-02
A4: Pusuyel Tedarik Örnek İşletme | B4: KURGUSAL PUSUYEL TEDARIK | C4: İzmir | F4: İzmir | H4: 2026-03
A5: Çınariz Dağıtım Örnek İşletme | B5: KURGUSAL CINARIZ DAGITIM | C5: Bursa | F5: Bursa | H5: 2026-04
A6: Ayvenk Ticaret Örnek İşletme | B6: KURGUSAL AYVENK TICARET | C6: Antalya | F6: Antalya | H6: 2026-05
A7: Kumsera Gıda Örnek İşletme | B7: KURGUSAL KUMSERA GIDA | C7: Konya | F7: Konya | H7: 2026-06
A8: Yelmino Market Örnek İşletme | B8: KURGUSAL YELMINO MARKET | C8: Kocaeli | F8: Kocaeli | H8: 2026-07
A9: Morçatı Tedarik Örnek İşletme | B9: KURGUSAL MORCATI TEDARIK | C9: Sakarya | F9: Sakarya | H9: 2026-08
A10: Gölvera Dağıtım Örnek İşletme | B10: KURGUSAL GOLVERA DAGITIM | C10: Kayseri | F10: Kayseri | H10: 2026-09
A11: Narvadi Ticaret Örnek İşletme | B11: KURGUSAL NARVADI TICARET | C11: Gaziantep | F11: Gaziantep | H11: 2026-10
A12: Çiyrota Gıda Örnek İşletme | B12: KURGUSAL CIYROTA GIDA | C12: İstanbul | H12: 2026-11
A13: Bulutiz Market Örnek İşletme | B13: KURGUSAL BULUTIZ MARKET | C13: Ankara | H13: 2026-12
A14: Kervola Tedarik Örnek İşletme | B14: KURGUSAL KERVOLA TEDARIK | C14: İzmir
A15: Ayserin Dağıtım Örnek İşletme | B15: KURGUSAL AYSERIN DAGITIM | C15: Bursa
A16: Yapriva Ticaret Örnek İşletme | B16: KURGUSAL YAPRIVA TICARET | C16: Antalya
A17: Denizova Gıda Örnek İşletme | B17: KURGUSAL DENIZOVA GIDA | C17: Konya
A18: Koralin Market Örnek İşletme | B18: KURGUSAL KORALIN MARKET | C18: Kocaeli
A19: Zerova Tedarik Örnek İşletme | B19: KURGUSAL ZEROVA TEDARIK | C19: Sakarya
A20: Ardılyel Dağıtım Örnek İşletme | B20: KURGUSAL ARDILYEL DAGITIM | C20: Kayseri
A21: Günsera Ticaret Örnek İşletme | B21: KURGUSAL GUNSERA TICARET | C21: Gaziantep
A22: Tanyuva Gıda Örnek İşletme | B22: KURGUSAL TANYUVA GIDA | C22: İstanbul
A23: Erguven Market Örnek İşletme | B23: KURGUSAL ERGUVEN MARKET | C23: Ankara
A24: Kumvadi Tedarik Örnek İşletme | B24: KURGUSAL KUMVADI TEDARIK | C24: İzmir
A25: Lalrota Dağıtım Örnek İşletme | B25: KURGUSAL LALROTA DAGITIM | C25: Bursa
A26: Çisenta Ticaret Örnek İşletme | B26: KURGUSAL CISENTA TICARET | C26: Antalya

Sheet Eşleştirme
A1: Tarih | B1: Açıklama | C1: Tutar | D1: Yapılacak | E1: Kaynak satır
A2: ='Panel'!$B$4&" / "&'Panel'!$N$4&" eşleşmeyen ödeme" -> 2026-10 / 3 eşleşmeyen ödeme
A3: Aranacak adı Müşteriler sayfasına ekleyin/düzeltin; liste kendiliğinden güncellenir.
A4: Tarih | B4: Açıklama | C4: Tutar | D4: Yapılacak
A5: =IF($E5="","",INDEX('Banka Dökümü'!$A$2:$A$2001,$E5)) -> 46303 | B5: =IF($E5="","",INDEX('Banka Dökümü'!$B$2:$B$2001,$E5)) -> FAST GELEN - BELIRSIZ GONDEREN 710 | C5: =IF($E5="","",INDEX('Banka Dökümü'!$C$2:$C$2001,$E5)) -> 5350 | D5: =IF(E5="","","Müşteri adı / aranacak ad / il bilgisini kontrol edin") -> Müşteri adı / aranacak ad / il bilgisini kontrol edin | E5: =IFERROR(MATCH(1,'Banka Dökümü'!$I$2:$I$2001,0),"") -> 67
A6: =IF($E6="","",INDEX('Banka Dökümü'!$A$2:$A$2001,$E6)) -> 46309 | B6: =IF($E6="","",INDEX('Banka Dökümü'!$B$2:$B$2001,$E6)) -> FAST GELEN - TANIMSIZ ISLETME 820 | C6: =IF($E6="","",INDEX('Banka Dökümü'!$C$2:$C$2001,$E6)) -> 7080.5 | D6: =IF(E6="","","Müşteri adı / aranacak ad / il bilgisini kontrol edin") -> Müşteri adı / aranacak ad / il bilgisini kontrol edin | E6: =IFERROR(MATCH(2,'Banka Dökümü'!$I$2:$I$2001,0),"") -> 77
A7: =IF($E7="","",INDEX('Banka Dökümü'!$A$2:$A$2001,$E7)) -> 46315 | B7: =IF($E7="","",INDEX('Banka Dökümü'!$B$2:$B$2001,$E7)) -> FAST GELEN - ACIKLAMASIZ TRANSFER 930 | C7: =IF($E7="","",INDEX('Banka Dökümü'!$C$2:$C$2001,$E7)) -> 8811 | D7: =IF(E7="","","Müşteri adı / aranacak ad / il bilgisini kontrol edin") -> Müşteri adı / aranacak ad / il bilgisini kontrol edin | E7: =IFERROR(MATCH(3,'Banka Dökümü'!$I$2:$I$2001,0),"") -> 88
A8: =IF($E8="","",INDEX('Banka Dökümü'!$A$2:$A$2001,$E8)) | B8: =IF($E8="","",INDEX('Banka Dökümü'!$B$2:$B$2001,$E8)) | C8: =IF($E8="","",INDEX('Banka Dökümü'!$C$2:$C$2001,$E8)) | D8: =IF(E8="","","Müşteri adı / aranacak ad / il bilgisini kontrol edin") | E8: =IFERROR(MATCH(4,'Banka Dökümü'!$I$2:$I$2001,0),"")
A9: =IF($E9="","",INDEX('Banka Dökümü'!$A$2:$A$2001,$E9)) | B9: =IF($E9="","",INDEX('Banka Dökümü'!$B$2:$B$2001,$E9)) | C9: =IF($E9="","",INDEX('Banka Dökümü'!$C$2:$C$2001,$E9)) | D9: =IF(E9="","","Müşteri adı / aranacak ad / il bilgisini kontrol edin") | E9: =IFERROR(MATCH(5,'Banka Dökümü'!$I$2:$I$2001,0),"")
A10: =IF($E10="","",INDEX('Banka Dökümü'!$A$2:$A$2001,$E10)) | B10: =IF($E10="","",INDEX('Banka Dökümü'!$B$2:$B$2001,$E10)) | C10: =IF($E10="","",INDEX('Banka Dökümü'!$C$2:$C$2001,$E10)) | D10: =IF(E10="","","Müşteri adı / aranacak ad / il bilgisini kontrol edin") | E10: =IFERROR(MATCH(6,'Banka Dökümü'!$I$2:$I$2001,0),"")
A11: =IF($E11="","",INDEX('Banka Dökümü'!$A$2:$A$2001,$E11)) | B11: =IF($E11="","",INDEX('Banka Dökümü'!$B$2:$B$2001,$E11)) | C11: =IF($E11="","",INDEX('Banka Dökümü'!$C$2:$C$2001,$E11)) | D11: =IF(E11="","","Müşteri adı / aranacak ad / il bilgisini kontrol edin") | E11: =IFERROR(MATCH(7,'Banka Dökümü'!$I$2:$I$2001,0),"")
A12: =IF($E12="","",INDEX('Banka Dökümü'!$A$2:$A$2001,$E12)) | B12: =IF($E12="","",INDEX('Banka Dökümü'!$B$2:$B$2001,$E12)) | C12: =IF($E12="","",INDEX('Banka Dökümü'!$C$2:$C$2001,$E12)) | D12: =IF(E12="","","Müşteri adı / aranacak ad / il bilgisini kontrol edin") | E12: =IFERROR(MATCH(8,'Banka Dökümü'!$I$2:$I$2001,0),"")
A13: =IF($E13="","",INDEX('Banka Dökümü'!$A$2:$A$2001,$E13)) | B13: =IF($E13="","",INDEX('Banka Dökümü'!$B$2:$B$2001,$E13)) | C13: =IF($E13="","",INDEX('Banka Dökümü'!$C$2:$C$2001,$E13)) | D13: =IF(E13="","","Müşteri adı / aranacak ad / il bilgisini kontrol edin") | E13: =IFERROR(MATCH(9,'Banka Dökümü'!$I$2:$I$2001,0),"")
A14: =IF($E14="","",INDEX('Banka Dökümü'!$A$2:$A$2001,$E14)) | B14: =IF($E14="","",INDEX('Banka Dökümü'!$B$2:$B$2001,$E14)) | C14: =IF($E14="","",INDEX('Banka Dökümü'!$C$2:$C$2001,$E14)) | D14: =IF(E14="","","Müşteri adı / aranacak ad / il bilgisini kontrol edin") | E14: =IFERROR(MATCH(10,'Banka Dökümü'!$I$2:$I$2001,0),"")
A15: =IF($E15="","",INDEX('Banka Dökümü'!$A$2:$A$2001,$E15)) | B15: =IF($E15="","",INDEX('Banka Dökümü'!$B$2:$B$2001,$E15)) | C15: =IF($E15="","",INDEX('Banka Dökümü'!$C$2:$C$2001,$E15)) | D15: =IF(E15="","","Müşteri adı / aranacak ad / il bilgisini kontrol edin") | E15: =IFERROR(MATCH(11,'Banka Dökümü'!$I$2:$I$2001,0),"")
A16: =IF($E16="","",INDEX('Banka Dökümü'!$A$2:$A$2001,$E16)) | B16: =IF($E16="","",INDEX('Banka Dökümü'!$B$2:$B$2001,$E16)) | C16: =IF($E16="","",INDEX('Banka Dökümü'!$C$2:$C$2001,$E16)) | D16: =IF(E16="","","Müşteri adı / aranacak ad / il bilgisini kontrol edin") | E16: =IFERROR(MATCH(12,'Banka Dökümü'!$I$2:$I$2001,0),"")
A17: =IF($E17="","",INDEX('Banka Dökümü'!$A$2:$A$2001,$E17)) | B17: =IF($E17="","",INDEX('Banka Dökümü'!$B$2:$B$2001,$E17)) | C17: =IF($E17="","",INDEX('Banka Dökümü'!$C$2:$C$2001,$E17)) | D17: =IF(E17="","","Müşteri adı / aranacak ad / il bilgisini kontrol edin") | E17: =IFERROR(MATCH(13,'Banka Dökümü'!$I$2:$I$2001,0),"")
A18: =IF($E18="","",INDEX('Banka Dökümü'!$A$2:$A$2001,$E18)) | B18: =IF($E18="","",INDEX('Banka Dökümü'!$B$2:$B$2001,$E18)) | C18: =IF($E18="","",INDEX('Banka Dökümü'!$C$2:$C$2001,$E18)) | D18: =IF(E18="","","Müşteri adı / aranacak ad / il bilgisini kontrol edin") | E18: =IFERROR(MATCH(14,'Banka Dökümü'!$I$2:$I$2001,0),"")
A19: =IF($E19="","",INDEX('Banka Dökümü'!$A$2:$A$2001,$E19)) | B19: =IF($E19="","",INDEX('Banka Dökümü'!$B$2:$B$2001,$E19)) | C19: =IF($E19="","",INDEX('Banka Dökümü'!$C$2:$C$2001,$E19)) | D19: =IF(E19="","","Müşteri adı / aranacak ad / il bilgisini kontrol edin") | E19: =IFERROR(MATCH(15,'Banka Dökümü'!$I$2:$I$2001,0),"")
A20: =IF($E20="","",INDEX('Banka Dökümü'!$A$2:$A$2001,$E20)) | B20: =IF($E20="","",INDEX('Banka Dökümü'!$B$2:$B$2001,$E20)) | C20: =IF($E20="","",INDEX('Banka Dökümü'!$C$2:$C$2001,$E20)) | D20: =IF(E20="","","Müşteri adı / aranacak ad / il bilgisini kontrol edin") | E20: =IFERROR(MATCH(16,'Banka Dökümü'!$I$2:$I$2001,0),"")
A21: =IF($E21="","",INDEX('Banka Dökümü'!$A$2:$A$2001,$E21)) | B21: =IF($E21="","",INDEX('Banka Dökümü'!$B$2:$B$2001,$E21)) | C21: =IF($E21="","",INDEX('Banka Dökümü'!$C$2:$C$2001,$E21)) | D21: =IF(E21="","","Müşteri adı / aranacak ad / il bilgisini kontrol edin") | E21: =IFERROR(MATCH(17,'Banka Dökümü'!$I$2:$I$2001,0),"")
A22: =IF($E22="","",INDEX('Banka Dökümü'!$A$2:$A$2001,$E22)) | B22: =IF($E22="","",INDEX('Banka Dökümü'!$B$2:$B$2001,$E22)) | C22: =IF($E22="","",INDEX('Banka Dökümü'!$C$2:$C$2001,$E22)) | D22: =IF(E22="","","Müşteri adı / aranacak ad / il bilgisini kontrol edin") | E22: =IFERROR(MATCH(18,'Banka Dökümü'!$I$2:$I$2001,0),"")
A23: =IF($E23="","",INDEX('Banka Dökümü'!$A$2:$A$2001,$E23)) | B23: =IF($E23="","",INDEX('Banka Dökümü'!$B$2:$B$2001,$E23)) | C23: =IF($E23="","",INDEX('Banka Dökümü'!$C$2:$C$2001,$E23)) | D23: =IF(E23="","","Müşteri adı / aranacak ad / il bilgisini kontrol edin") | E23: =IFERROR(MATCH(19,'Banka Dökümü'!$I$2:$I$2001,0),"")
A24: =IF($E24="","",INDEX('Banka Dökümü'!$A$2:$A$2001,$E24)) | B24: =IF($E24="","",INDEX('Banka Dökümü'!$B$2:$B$2001,$E24)) | C24: =IF($E24="","",INDEX('Banka Dökümü'!$C$2:$C$2001,$E24)) | D24: =IF(E24="","","Müşteri adı / aranacak ad / il bilgisini kontrol edin") | E24: =IFERROR(MATCH(20,'Banka Dökümü'!$I$2:$I$2001,0),"")
A25: =IF($E25="","",INDEX('Banka Dökümü'!$A$2:$A$2001,$E25)) | B25: =IF($E25="","",INDEX('Banka Dökümü'!$B$2:$B$2001,$E25)) | C25: =IF($E25="","",INDEX('Banka Dökümü'!$C$2:$C$2001,$E25)) | D25: =IF(E25="","","Müşteri adı / aranacak ad / il bilgisini kontrol edin") | E25: =IFERROR(MATCH(21,'Banka Dökümü'!$I$2:$I$2001,0),"")
A26: =IF($E26="","",INDEX('Banka Dökümü'!$A$2:$A$2001,$E26)) | B26: =IF($E26="","",INDEX('Banka Dökümü'!$B$2:$B$2001,$E26)) | C26: =IF($E26="","",INDEX('Banka Dökümü'!$C$2:$C$2001,$E26)) | D26: =IF(E26="","","Müşteri adı / aranacak ad / il bilgisini kontrol edin") | E26: =IFERROR(MATCH(22,'Banka Dökümü'!$I$2:$I$2001,0),"")
A27: =IF($E27="","",INDEX('Banka Dökümü'!$A$2:$A$2001,$E27)) | B27: =IF($E27="","",INDEX('Banka Dökümü'!$B$2:$B$2001,$E27)) | C27: =IF($E27="","",INDEX('Banka Dökümü'!$C$2:$C$2001,$E27)) | D27: =IF(E27="","","Müşteri adı / aranacak ad / il bilgisini kontrol edin") | E27: =IFERROR(MATCH(23,'Banka Dökümü'!$I$2:$I$2001,0),"")
A28: =IF($E28="","",INDEX('Banka Dökümü'!$A$2:$A$2001,$E28)) | B28: =IF($E28="","",INDEX('Banka Dökümü'!$B$2:$B$2001,$E28)) | C28: =IF($E28="","",INDEX('Banka Dökümü'!$C$2:$C$2001,$E28)) | D28: =IF(E28="","","Müşteri adı / aranacak ad / il bilgisini kontrol edin") | E28: =IFERROR(MATCH(24,'Banka Dökümü'!$I$2:$I$2001,0),"")
A29: =IF($E29="","",INDEX('Banka Dökümü'!$A$2:$A$2001,$E29)) | B29: =IF($E29="","",INDEX('Banka Dökümü'!$B$2:$B$2001,$E29)) | C29: =IF($E29="","",INDEX('Banka Dökümü'!$C$2:$C$2001,$E29)) | D29: =IF(E29="","","Müşteri adı / aranacak ad / il bilgisini kontrol edin") | E29: =IFERROR(MATCH(25,'Banka Dökümü'!$I$2:$I$2001,0),"")
A30: =IF($E30="","",INDEX('Banka Dökümü'!$A$2:$A$2001,$E30)) | B30: =IF($E30="","",INDEX('Banka Dökümü'!$B$2:$B$2001,$E30)) | C30: =IF($E30="","",INDEX('Banka Dökümü'!$C$2:$C$2001,$E30)) | D30: =IF(E30="","","Müşteri adı / aranacak ad / il bilgisini kontrol edin") | E30: =IFERROR(MATCH(26,'Banka Dökümü'!$I$2:$I$2001,0),"")
A31: =IF($E31="","",INDEX('Banka Dökümü'!$A$2:$A$2001,$E31)) | B31: =IF($E31="","",INDEX('Banka Dökümü'!$B$2:$B$2001,$E31)) | C31: =IF($E31="","",INDEX('Banka Dökümü'!$C$2:$C$2001,$E31)) | D31: =IF(E31="","","Müşteri adı / aranacak ad / il bilgisini kontrol edin") | E31: =IFERROR(MATCH(27,'Banka Dökümü'!$I$2:$I$2001,0),"")
A32: =IF($E32="","",INDEX('Banka Dökümü'!$A$2:$A$2001,$E32)) | B32: =IF($E32="","",INDEX('Banka Dökümü'!$B$2:$B$2001,$E32)) | C32: =IF($E32="","",INDEX('Banka Dökümü'!$C$2:$C$2001,$E32)) | D32: =IF(E32="","","Müşteri adı / aranacak ad / il bilgisini kontrol edin") | E32: =IFERROR(MATCH(28,'Banka Dökümü'!$I$2:$I$2001,0),"")
A33: =IF($E33="","",INDEX('Banka Dökümü'!$A$2:$A$2001,$E33)) | B33: =IF($E33="","",INDEX('Banka Dökümü'!$B$2:$B$2001,$E33)) | C33: =IF($E33="","",INDEX('Banka Dökümü'!$C$2:$C$2001,$E33)) | D33: =IF(E33="","","Müşteri adı / aranacak ad / il bilgisini kontrol edin") | E33: =IFERROR(MATCH(29,'Banka Dökümü'!$I$2:$I$2001,0),"")
A34: =IF($E34="","",INDEX('Banka Dökümü'!$A$2:$A$2001,$E34)) | B34: =IF($E34="","",INDEX('Banka Dökümü'!$B$2:$B$2001,$E34)) | C34: =IF($E34="","",INDEX('Banka Dökümü'!$C$2:$C$2001,$E34)) | D34: =IF(E34="","","Müşteri adı / aranacak ad / il bilgisini kontrol edin") | E34: =IFERROR(MATCH(30,'Banka Dökümü'!$I$2:$I$2001,0),"")
A35: =IF($E35="","",INDEX('Banka Dökümü'!$A$2:$A$2001,$E35)) | B35: =IF($E35="","",INDEX('Banka Dökümü'!$B$2:$B$2001,$E35)) | C35: =IF($E35="","",INDEX('Banka Dökümü'!$C$2:$C$2001,$E35)) | D35: =IF(E35="","","Müşteri adı / aranacak ad / il bilgisini kontrol edin") | E35: =IFERROR(MATCH(31,'Banka Dökümü'!$I$2:$I$2001,0),"")
A36: =IF($E36="","",INDEX('Banka Dökümü'!$A$2:$A$2001,$E36)) | B36: =IF($E36="","",INDEX('Banka Dökümü'!$B$2:$B$2001,$E36)) | C36: =IF($E36="","",INDEX('Banka Dökümü'!$C$2:$C$2001,$E36)) | D36: =IF(E36="","","Müşteri adı / aranacak ad / il bilgisini kontrol edin") | E36: =IFERROR(MATCH(32,'Banka Dökümü'!$I$2:$I$2001,0),"")
A37: =IF($E37="","",INDEX('Banka Dökümü'!$A$2:$A$2001,$E37)) | B37: =IF($E37="","",INDEX('Banka Dökümü'!$B$2:$B$2001,$E37)) | C37: =IF($E37="","",INDEX('Banka Dökümü'!$C$2:$C$2001,$E37)) | D37: =IF(E37="","","Müşteri adı / aranacak ad / il bilgisini kontrol edin") | E37: =IFERROR(MATCH(33,'Banka Dökümü'!$I$2:$I$2001,0),"")
A38: =IF($E38="","",INDEX('Banka Dökümü'!$A$2:$A$2001,$E38)) | B38: =IF($E38="","",INDEX('Banka Dökümü'!$B$2:$B$2001,$E38)) | C38: =IF($E38="","",INDEX('Banka Dökümü'!$C$2:$C$2001,$E38)) | D38: =IF(E38="","","Müşteri adı / aranacak ad / il bilgisini kontrol edin") | E38: =IFERROR(MATCH(34,'Banka Dökümü'!$I$2:$I$2001,0),"")
A39: =IF($E39="","",INDEX('Banka Dökümü'!$A$2:$A$2001,$E39)) | B39: =IF($E39="","",INDEX('Banka Dökümü'!$B$2:$B$2001,$E39)) | C39: =IF($E39="","",INDEX('Banka Dökümü'!$C$2:$C$2001,$E39)) | D39: =IF(E39="","","Müşteri adı / aranacak ad / il bilgisini kontrol edin") | E39: =IFERROR(MATCH(35,'Banka Dökümü'!$I$2:$I$2001,0),"")
A40: =IF($E40="","",INDEX('Banka Dökümü'!$A$2:$A$2001,$E40)) | B40: =IF($E40="","",INDEX('Banka Dökümü'!$B$2:$B$2001,$E40)) | C40: =IF($E40="","",INDEX('Banka Dökümü'!$C$2:$C$2001,$E40)) | D40: =IF(E40="","","Müşteri adı / aranacak ad / il bilgisini kontrol edin") | E40: =IFERROR(MATCH(36,'Banka Dökümü'!$I$2:$I$2001,0),"")
...

Sheet Nasıl kullanılır
A1: NASIL KULLANILIR / 5 ADIM
A3: 01 | B3: Banka Dökümü sayfasında A:D alanına gerçek tarih, açıklama, tutar ve bakiye yapıştırın. Girişler pozitif, çıkışlar negatif olmalı; E:I formüllerini silmeyin.
A4: 02 | B4: Satışlar sayfasında A:E alanına tarih, fatura no, müşteri, il ve tutar girin. F sütunu ayı hesaplar. Eski veriyi değiştiriyorsanız kalan eski satırları da temizleyin.
A5: 03 | B5: Müşteriler sayfasına müşteri, bankada aranacak ayırt edici kısa ad ve il ekleyin. Boş, yinelenen veya birden çok müşteriyi çağrıştıran ad kullanmayın (en fazla 100 müşteri).
A6: 04 | B6: Panel sayfasında B4 hücresinden ayı seçin. Satış, tahsilat, ay içi alacak farkı, önceki ay karşılaştırması ve grafik birlikte güncellenir.
A7: 05 | B7: Paneldeki uyarıya tıklayın. Eşleştirme listesindeki girişler için müşteri/aranacak ad/il bilgisini düzeltin; tek eşleşme sağlanınca ödeme tahsilata katılır.
A10: TASLAK • Örnek işletmeler ve işlemler kurgusaldır. Gerçek müşteri verisi yoktur.
A12: Kapasite: 2.000 satış + 2.000 banka satırı / 100 müşteri. Gri alanlar hesaplanır; formüllere yapıştırmayın.
A13: Alacak = seçilen ay satışı − o ayın eşleşen tahsilatı. Açılış bakiyesi ve fatura/vade takibi içermez.
A14: Yeni ay/yıl için Müşteriler!H2:H13 ay listesini güncelleyin. İller bu taslakta sabit 10 ildir.
